<?xml version="1.0"?>
<robot name="box">
  <!-- Define the material properties -->
  <material name="blue">
    <color rgba="0 0 1 1"/>
  </material>

  <!-- Define the link -->
  <link name="world"/>

  <link name="box_link">
    <visual>
      <origin xyz="0 0 0" rpy="0 0 0"/>
      <geometry>
        <box size="0.5 0.5 0.5"/>
      </geometry>
      <material name="blue"/>
    </visual>
    <collision>
      <origin xyz="0 0 0" rpy="0 0 0"/>
      <geometry>
        <box size="0.5 0.5 0.5"/>
      </geometry>
    </collision>
    <inertial>
      <mass value="1"/>
      <origin xyz="0 0 0" rpy="0 0 0"/>
      <inertia ixx="0.0833" ixy="0" ixz="0" iyy="0.0833" iyz="0" izz="0.0833"/>
    </inertial>
  </link>

    <!-- <link name="box_link2">
    <visual>
      <origin xyz="1 1 1" rpy="0 0 0"/>
      <geometry>
        <box size="0.5 0.5 0.5"/>
      </geometry>
      <material name="blue"/>
    </visual>
    <collision>
      <origin xyz="0 0 0" rpy="0 0 0"/>
      <geometry>
        <box size="0.5 0.5 0.5"/>
      </geometry>
    </collision>
    <inertial>
      <mass value="1"/>
      <origin xyz="0 0 0" rpy="0 0 0"/>
      <inertia ixx="0.0833" ixy="0" ixz="0" iyy="0.0833" iyz="0" izz="0.0833"/>
    </inertial>
  </link> -->

  <!-- Define the joint -->
  <joint name="box_joint" type="continuous">
    <parent link="world"/>
    <child link="box_link"/>
    <origin xyz="0 0 0" rpy="0 0 0"/>
    <axis xyz="1 1 1"/>
    <!-- <limit lower="-3.1416" upper="3.1416" effort="10" velocity="3.1416"/> -->
  </joint>
</robot>
